Workbook

Sheet Cover
B2: TEST CASE
B3: Version: | C3: 1
B4: Issue date: | C4: 46310
B6: Project Name: | C6: TechStore - Website bán hàng đồ công nghệ
B7: Project Code: | C7: TECHSTORE
B10: Record of change:
B11: Effective Date | C11: Version | D11: Change location | E11: Change description | F11: Originator | G11: Reviewer/ Approver | H11: Reference
B12: 46310 | C12: 1 | D12: All modules | E12: Tạo bộ test case cho toàn bộ website TechStore | F12: Nhóm TechStore | G12: Test Leader | H12: Test Plan TechStore

Sheet TechStore Test Cases
A1: TEST CASE
A3: System Name: | B3: TechStore
A4: Module Code: | B4: TS-ALL - E-commerce website
A5: Test requirement: | B5: Functional, UI/UX, security, database và compatibility
A6: Pass | B6: =COUNTIF(I12:I216,"Pass") -> 179 | C6: Pending | D6: =COUNTIF(I12:I216,"Pending") -> 0
A7: Fail | B7: =COUNTIF(I12:I216,"Fail") -> 9 | C7: Number of test cases: | D7: =COUNTA(A12:A216)-17 -> 188
A9: ID | B9: Test Case Description | C9: Test Case Procedure | D9: Expected Output | H9: Test date | I9: Result | J9: Note
A12: 5.1. Hệ thống và điều hướng
A13: SYS-01 | B13: Mở / và /home. | C13: 1. Mở TechStore trên môi trường test. 2. Không đăng nhập, trừ khi test case yêu cầu vai trò cụ thể. 3. Thực hiện: Mở / và /home. 4. Ghi nhận UI, HTTP response, log và dữ liệu database liên quan. | D13: Vào được trang chủ, HTTP 200, không lỗi font/ảnh. | H13: 46310 | I13: Pass | J13: Ưu tiên: P1 HTTP probe: / và /home đều HTTP 200; main.css HTTP 200 (63.586 byte); trang khai báo UTF-8.
A14: SYS-02 | B14: Mở /health khi SQL Server hoạt động. | C14: 1. Mở TechStore trên môi trường test. 2. Không đăng nhập, trừ khi test case yêu cầu vai trò cụ thể. 3. Thực hiện: Mở /health khi SQL Server hoạt động. 4. Ghi nhận UI, HTTP response, log và dữ liệu database liên quan. | D14: Báo ứng dụng và database hoạt động. | H14: 46310 | I14: Pass | J14: Ưu tiên: P0 Tomcat sạch trả /health HTTP 200; bộ integration sử dụng SQL Server hoàn tất 36/36 kiểm tra.
A15: SYS-03 | B15: Tắt database rồi mở /health và /home, sau đó bật lại. | C15: 1. Mở TechStore trên môi trường test. 2. Không đăng nhập, trừ khi test case yêu cầu vai trò cụ thể. 3. Thực hiện: Tắt database rồi mở /health và /home, sau đó bật lại. 4. Ghi nhận UI, HTTP response, log và dữ liệu database liên quan. | D15: Health báo lỗi có kiểm soát; trang không lộ stack trace/mật khẩu. | H15: 46310 | I15: Pass | J15: Ưu tiên: P1 Batch 1/3 - 15/10/2026 - Pass: Fault-injection trên Tomcat cô lập với DB không truy cập được: /health HTTP 200 báo “Chưa kết nối”, /home HTTP 200 hiển thị cảnh báo có kiểm soát; UI không lộ password, stack trace hoặc exception nội bộ.
A16: SYS-04 | B16: Mở URL không tồn tại. | C16: 1. Mở TechStore trên môi trường test. 2. Không đăng nhập, trừ khi test case yêu cầu vai trò cụ thể. 3. Thực hiện: Mở URL không tồn tại. 4. Ghi nhận UI, HTTP response, log và dữ liệu database liên quan. | D16: HTTP 404 và trang lỗi đúng layout. | H16: 46310 | I16: Pass | J16: Ưu tiên: P1 URL không tồn tại trả HTTP 404 và hiển thị trang lỗi có mã 404.
A17: SYS-05 | B17: Mở trực tiếp /WEB-INF/views/home.jsp. | C17: 1. Mở TechStore trên môi trường test. 2. Không đăng nhập, trừ khi test case yêu cầu vai trò cụ thể. 3. Thực hiện: Mở trực tiếp /WEB-INF/views/home.jsp. 4. Ghi nhận UI, HTTP response, log và dữ liệu database liên quan. | D17: Không truy cập trực tiếp được JSP. | H17: 46310 | I17: Pass | J17: Ưu tiên: P1 Truy cập trực tiếp /WEB-INF/views/home.jsp trả HTTP 404.
A18: SYS-06 | B18: Đi qua logo, header, menu danh mục, footer, Back/Forward. | C18: 1. Mở TechStore trên môi trường test. 2. Không đăng nhập, trừ khi test case yêu cầu vai trò cụ thể. 3. Thực hiện: Đi qua logo, header, menu danh mục, footer, Back/Forward. 4. Ghi nhận UI, HTTP response, log và dữ liệu database liên quan. | D18: URL, trạng thái menu và lịch sử trình duyệt đúng. | H18: 46310 | I18: Pass | J18: Ưu tiên: P2 Batch 1/3 - 15/10/2026 - Pass: logo=/TechStore/home; back=http://localhost:8080/TechStore/home; forward=http://localhost:8080/TechStore/products; header/footer=1/1
A19: 5.2. Đăng ký, đăng nhập và session
A20: AUTH-01 | B20: Đăng ký với dữ liệu hợp lệ. | C20: 1. Mở TechStore trên môi trường test. 2. Chuẩn bị tài khoản và dữ liệu authentication theo nội dung test case. 3. Thực hiện: Đăng ký với dữ liệu hợp lệ. 4. Ghi nhận UI, HTTP response, log và dữ liệu database liên quan. | D20: Tạo CUSTOMER/ACTIVE, mật khẩu không lưu dạng rõ, chuyển đến đăng nhập. | H20: 46310 | I20: Pass | J20: Ưu tiên: P0 Integration test đăng ký thành công, chuyển đến /login; SQL kiểm tra 3/3 mật khẩu đang lưu dạng BCrypt.
A21: AUTH-02 | B21: Nhập email có chữ hoa và khoảng trắng. | C21: 1. Mở TechStore trên môi trường test. 2. Chuẩn bị tài khoản và dữ liệu authentication theo nội dung test case. 3. Thực hiện: Nhập email có chữ hoa và khoảng trắng. 4. Ghi nhận UI, HTTP response, log và dữ liệu database liên quan. | D21: Email được trim, lưu chữ thường và đăng nhập được. | H21: 46310 | I21: Pass | J21: Ưu tiên: P1 Batch 1/3 - 15/10/2026 - Pass: DB normalized email/phone/nameLength=codex.batch1.20261015092634.upper@techstore.local|0901234567|16; login=http://localhost:8080/TechStore/home
A22: AUTH-03 | B22: Thử email sai định dạng và email dài quá giới hạn. | C22: 1. Mở TechStore trên môi trường test. 2. Chuẩn bị tài khoản và dữ liệu authentication theo nội dung test case. 3. Thực hiện: Thử email sai định dạng và email dài quá giới hạn. 4. Ghi nhận UI, HTTP response, log và dữ liệu database liên quan. | D22: Hiển thị lỗi, không tạo user. | H22: 46310 | I22: Pass | J22: Ưu tiên: P1 Batch 1/3 - 15/10/2026 - Pass: rows=0; invalid/long validation=true/true
A23: AUTH-04 | B23: Đăng ký lại email đã tồn tại, kể cả khác hoa/thường. | C23: 1. Mở TechStore trên môi trường test. 2. Chuẩn bị tài khoản và dữ liệu authentication theo nội dung test case. 3. Thực hiện: Đăng ký lại email đã tồn tại, kể cả khác hoa/thường. 4. Ghi nhận UI, HTTP response, log và dữ liệu database liên quan. | D23: Bị từ chối, không tạo bản ghi trùng. | H23: 46310 | I23: Pass | J23: Ưu tiên: P0 Integration test từ chối email trùng; database không tạo thêm bản ghi.
A24: AUTH-05 | B24: Thử họ tên rỗng và dài hơn 150 ký tự. | C24: 1. Mở TechStore trên môi trường test. 2. Chuẩn bị tài khoản và dữ liệu authentication theo nội dung test case. 3. Thực hiện: Thử họ tên rỗng và dài hơn 150 ký tự. 4. Ghi nhận UI, HTTP response, log và dữ liệu database liên quan. | D24: Bị từ chối, giữ dữ liệu form hợp lý. | H24: 46310 | I24: Pass | J24: Ưu tiên: P1 Batch 1/3 - 15/10/2026 - Pass: rows=0
A25: AUTH-06 | B25: Thử số điện thoại 090..., định dạng +84, có dấu cách/gạch và số sai. | C25: 1. Mở TechStore trên môi trường test. 2. Chuẩn bị tài khoản và dữ liệu authentication theo nội dung test case. 3. Thực hiện: Thử số điện thoại 090..., định dạng +84, có dấu cách/gạch và số sai. 4. Ghi nhận UI, HTTP response, log và dữ liệu database liên quan. | D25: Chuẩn hóa số hợp lệ; từ chối số không đủ 10 chữ số/bắt đầu sai. | H25: 46310 | I25: Pass | J25: Ưu tiên: P1 Batch 1/3 - 15/10/2026 - Pass: p090:0901234567; p84:0901234567; pspace:0901234567; pinvalid:rejected
A26: AUTH-07 | B26: Thử mật khẩu 7, 8, 72, 73 ký tự và xác nhận không khớp. | C26: 1. Mở TechStore trên môi trường test. 2. Chuẩn bị tài khoản và dữ liệu authentication theo nội dung test case. 3. Thực hiện: Thử mật khẩu 7, 8, 72, 73 ký tự và xác nhận không khớp. 4. Ghi nhận UI, HTTP response, log và dữ liệu database liên quan. | D26: Chỉ 8–72 ký tự và xác nhận đúng được chấp nhận. | H26: 46310 | I26: Pass | J26: Ưu tiên: P0 Batch 1/3 - 15/10/2026 - Pass: 7:0; 8:1; 72:1; 73:0; mismatch:0
A27: AUTH-08 | B27: Đăng nhập đúng/sai mật khẩu và email không tồn tại. | C27: 1. Mở TechStore trên môi trường test. 2. Chuẩn bị tài khoản và dữ liệu authentication theo nội dung test case. 3. Thực hiện: Đăng nhập đúng/sai mật khẩu và email không tồn tại. 4. Ghi nhận UI, HTTP response, log và dữ liệu database liên quan. | D27: Đúng thì tạo session; sai dùng thông báo chung, không lộ nguyên nhân. | H27: 46310 | I27: Pass | J27: Ưu tiên: P0 Integration test đăng nhập đúng tạo session và mật khẩu sai bị từ chối bằng thông báo chung.
A28: AUTH-09 | B28: Khóa user rồi thử đăng nhập. | C28: 1. Mở TechStore trên môi trường test. 2. Chuẩn bị tài khoản và dữ liệu authentication theo nội dung test case. 3. Thực hiện: Khóa user rồi thử đăng nhập. 4. Ghi nhận UI, HTTP response, log và dữ liệu database liên quan. | D28: Không đăng nhập được. | H28: 46310 | I28: Pass | J28: Ưu tiên: P0 Batch 1/3 - 15/10/2026 - Pass: loginUrl=http://localhost:8080/TechStore/login; error=true
A29: AUTH-10 | B29: Mở /cart khi chưa đăng nhập, sau đó đăng nhập. | C29: 1. Mở TechStore trên môi trường test. 2. Chuẩn bị tài khoản và dữ liệu authentication theo nội dung test case. 3. Thực hiện: Mở /cart khi chưa đăng nhập, sau đó đăng nhập. 4. Ghi nhận UI, HTTP response, log và dữ liệu database liên quan. | D29: Chuyển về /cart; không mất query string ở URL đã lưu. | H29: 46310 | I29: Pass | J29: Ưu tiên: P1 Batch 1/3 - 15/10/2026 - Pass: redirect=http://localhost:8080/TechStore/cart?source=batch1
A30: AUTH-11 | B30: Đăng nhập admin từ trang login bình thường. | C30: 1. Mở TechStore trên môi trường test. 2. Chuẩn bị tài khoản và dữ liệu authentication theo nội dung test case. 3. Thực hiện: Đăng nhập admin từ trang login bình thường. 4. Ghi nhận UI, HTTP response, log và dữ liệu database liên quan. | D30: Chuyển thẳng đến /admin. | H30: 46310 | I30: Pass | J30: Ưu tiên: P0 Tài khoản test được gán ADMIN, đăng nhập thành công và mở được /admin cùng bốn trang quản trị, đều HTTP 200.
A31: AUTH-12 | B31: Khách cố mở /admin; người chưa login mở /admin. | C31: 1. Mở TechStore trên môi trường test. 2. Chuẩn bị tài khoản và dữ liệu authentication theo nội dung test case. 3. Thực hiện: Khách cố mở /admin; người chưa login mở /admin. 4. Ghi nhận UI, HTTP response, log và dữ liệu database liên quan. | D31: Khách nhận 403; người chưa login chuyển login rồi về admin nếu đăng nhập admin. | H31: 46310 | I31: Pass | J31: Ưu tiên: P0 CUSTOMER nhận HTTP 403 tại admin; người chưa đăng nhập nhận HTTP 302 về /login; ADMIN truy cập được sau đăng nhập.
... A34: AUTH-15 | B34: Không thao tác 30 phút rồi truy cập trang bảo vệ. | C34: 1. Mở TechStore trên môi trường test. 2. Chuẩn bị tài khoản và dữ liệu authentication theo nội dung test case. 3. Thực hiện: Không thao tác 30 phút rồi truy cập trang bảo vệ. 4. Ghi nhận UI, HTTP response, log và dữ liệu database liên quan. | D34: Session hết hạn và yêu cầu đăng nhập lại. | H34: 46310 | I34: Pass | J34: Ưu tiên: P1 Batch 1/3 - 15/10/2026 - Pass: Đối chiếu web.xml session-timeout=30 phút và chạy Tomcat StandardSession với idle 31 phút: session bị invalid, trang bảo vệ sẽ yêu cầu đăng nhập lại.
A35: 5.3. Quên và đặt lại mật khẩu
A36: RESET-01 | B36: Gửi email tồn tại, không tồn tại và sai định dạng. | C36: 1. Mở TechStore trên môi trường test. 2. Chuẩn bị tài khoản và dữ liệu authentication theo nội dung test case. 3. Thực hiện: Gửi email tồn tại, không tồn tại và sai định dạng. 4. Ghi nhận UI, HTTP response, log và dữ liệu database liên quan. | D36: Giao diện luôn trả cùng thông báo chung. | H36: 46310 | I36: Pass | J36: Ưu tiên: P1 Batch 1/3 - 15/10/2026 - Pass: generic response present=true/true/true
A37: RESET-02 | B37: Kiểm tra email reset của tài khoản active. | C37: 1. Mở TechStore trên môi trường test. 2. Chuẩn bị tài khoản và dữ liệu authentication theo nội dung test case. 3. Thực hiện: Kiểm tra email reset của tài khoản active. 4. Ghi nhận UI, HTTP response, log và dữ liệu database liên quan. | D37: Link dùng đúng app.url, có token; database chỉ lưu hash, không lưu token thô. | H37: 46310 | I37: Pass | J37: Ưu tiên: P0 Batch 1/3 - 15/10/2026 - Pass: mail=true; app.url=true; tokenLength=43; DB stores matching SHA-256 only=true
A38: RESET-03 | B38: Dùng token hợp lệ đổi mật khẩu 8–72 ký tự. | C38: 1. Mở TechStore trên môi trường test. 2. Chuẩn bị tài khoản và dữ liệu authentication theo nội dung test case. 3. Thực hiện: Dùng token hợp lệ đổi mật khẩu 8–72 ký tự. 4. Ghi nhận UI, HTTP response, log và dữ liệu database liên quan. | D38: Đổi thành công; mật khẩu cũ thất bại, mật khẩu mới đăng nhập được. | H38: 46310 | I38: Pass | J38: Ưu tiên: P0 Batch 1/3 - 15/10/2026 - Pass: old/new login=http://localhost:8080/TechStore/login/http://localhost:8080/TechStore/home; used=1
A39: RESET-04 | B39: Dùng lại token đã dùng. | C39: 1. Mở TechStore trên môi trường test. 2. Chuẩn bị tài khoản và dữ liệu authentication theo nội dung test case. 3. Thực hiện: Dùng lại token đã dùng. 4. Ghi nhận UI, HTTP response, log và dữ liệu database liên quan. | D39: Bị từ chối. | H39: 46310 | I39: Pass | J39: Ưu tiên: P0 Batch 1/3 - 15/10/2026 - Pass: reuse rejected=true
A40: RESET-05 | B40: Dùng token sai, rỗng, quá 200 ký tự hoặc token quá 30 phút. | C40: 1. Mở TechStore trên môi trường test. 2. Chuẩn bị tài khoản và dữ liệu authentication theo nội dung test case. 3. Thực hiện: Dùng token sai, rỗng, quá 200 ký tự hoặc token quá 30 phút. 4. Ghi nhận UI, HTTP response, log và dữ liệu database liên quan. | D40: Bị từ chối bằng thông báo an toàn. | H40: 46310 | I40: Pass | J40: Ưu tiên: P0 Batch 1/3 - 15/10/2026 - Pass: HTTP đã từ chối token sai, rỗng và dài 201 ký tự; focused production-service probe xác nhận đủ 4/4 trường hợp, gồm token hết hạn do DAO trả consume=false.
A41: RESET-06 | B41: Yêu cầu link mới khi link cũ còn hiệu lực. | C41: 1. Mở TechStore trên môi trường test. 2. Chuẩn bị tài khoản và dữ liệu authentication theo nội dung test case. 3. Thực hiện: Yêu cầu link mới khi link cũ còn hiệu lực. 4. Ghi nhận UI, HTTP response, log và dữ liệu database liên quan. | D41: Token active cũ bị thay thế/không còn dùng được. | H41: 46310 | I41: Pass | J41: Ưu tiên: P1 Batch 1/3 - 15/10/2026 - Pass: active|oldInvalidated=1|1
A42: RESET-07 | B42: Gửi 4 lần trong 15 phút cho cùng tài khoản. | C42: 1. Mở TechStore trên môi trường test. 2. Chuẩn bị tài khoản và dữ liệu authentication theo nội dung test case. 3. Thực hiện: Gửi 4 lần trong 15 phút cho cùng tài khoản. 4. Ghi nhận UI, HTTP response, log và dữ liệu database liên quan. | D42: Tối đa 3 yêu cầu được tạo/gửi; phản hồi không lộ việc bị giới hạn. | H42: 46310 | I42: Pass | J42: Ưu tiên: P1 Batch 1/3 - 15/10/2026 - Pass: Đã gửi 4 request HTTP; truy vấn ban đầu dùng SYSDATETIME local trong khi Hibernate lưu UTC nên đếm sai. Focused service probe với cùng rate-window xác nhận chỉ 3/4 token được tạo.
A43: RESET-08 | B43: Gỡ cấu hình mail và thử gửi. | C43: 1. Mở TechStore trên môi trường test. 2. Chuẩn bị tài khoản và dữ liệu authentication theo nội dung test case. 3. Thực hiện: Gỡ cấu hình mail và thử gửi. 4. Ghi nhận UI, HTTP response, log và dữ liệu database liên quan. | D43: Không lộ mật khẩu/stack trace ra UI; token thất bại được vô hiệu hóa. | H43: 46310 | I43: Pass | J43: Ưu tiên: P1 Batch 1/3 - 15/10/2026 - Pass: Chạy PasswordResetServiceImpl không có TECHSTORE_MAIL_*: token SHA-256 được tạo rồi invalidate; exception an toàn, không chứa tên biến mật khẩu. ForgotPasswordServlet dùng thông báo chung và không đưa stack trace ra UI.
A44: 5.4. Trang chủ, catalog và chi tiết sản phẩm
A45: CAT-01 | B45: Mở trang chủ với dữ liệu mẫu. | C45: 1. Mở TechStore trên môi trường test. 2. Không đăng nhập, trừ khi test case yêu cầu vai trò cụ thể. 3. Thực hiện: Mở trang chủ với dữ liệu mẫu. 4. Ghi nhận UI, HTTP response, log và dữ liệu database liên quan. | D45: Hiển thị tối đa 8 sản phẩm mới và tối đa 4 sản phẩm mỗi danh mục có dữ liệu. | H45: 46310 | I45: Pass | J45: Ưu tiên: P1 Batch 1/3 - 15/10/2026 - Pass: Trang chủ hiển thị 8 sản phẩm mới; 4 section danh mục lần lượt 4,4,4,4 sản phẩm. Selector ban đầu đếm nhầm block featured thêm một lần.
A46: CAT-02 | B46: Tìm theo tên/từ khóa tiếng Việt, hoa/thường và từ không tồn tại. | C46: 1. Mở TechStore trên môi trường test. 2. Không đăng nhập, trừ khi test case yêu cầu vai trò cụ thể. 3. Thực hiện: Tìm theo tên/từ khóa tiếng Việt, hoa/thường và từ không tồn tại. 4. Ghi nhận UI, HTTP response, log và dữ liệu database liên quan. | D46: Kết quả đúng; trường hợp rỗng có thông báo phù hợp. | H46: 46310 | I46: Pass | J46: Ưu tiên: P1 Batch 1/3 - 15/10/2026 - Pass: keyword=Laptop; lower/upper=10/10; emptyState=1
...

Sheet Test Report
A1: TEST REPORT
B3: Note: | C3: 15/10/2026: Hoàn tất đợt 3/3 (50 test case): 45 Pass, 5 Fail. Tổng kết quả: 179 Pass, 9 Fail, 0 Pending. Đã kiểm tra admin, security, transaction, database, UI/accessibility, hiệu năng và deploy; dữ liệu test tạm được dọn sau khi ghi nhận.
B4: Date | C4: 46310
B7: No | C7: Module code | D7: Pass | E7: Fail | F7: Pending | G7: Number of test cases
B8: 1 | C8: 5.1 - Hệ thống và điều hướng | D8: =COUNTIF('TechStore Test Cases'!I13:I18,"Pass") -> 6 | E8: =COUNTIF('TechStore Test Cases'!I13:I18,"Fail") -> 0 | F8: =COUNTIF('TechStore Test Cases'!I13:I18,"Pending") -> 0 | G8: =COUNTA('TechStore Test Cases'!A13:A18) -> 6
B9: 2 | C9: 5.2 - Đăng ký, đăng nhập và session | D9: =COUNTIF('TechStore Test Cases'!I20:I34,"Pass") -> 15 | E9: =COUNTIF('TechStore Test Cases'!I20:I34,"Fail") -> 0 | F9: =COUNTIF('TechStore Test Cases'!I20:I34,"Pending") -> 0 | G9: =COUNTA('TechStore Test Cases'!A20:A34) -> 15
B10: 3 | C10: 5.3 - Quên và đặt lại mật khẩu | D10: =COUNTIF('TechStore Test Cases'!I36:I43,"Pass") -> 8 | E10: =COUNTIF('TechStore Test Cases'!I36:I43,"Fail") -> 0 | F10: =COUNTIF('TechStore Test Cases'!I36:I43,"Pending") -> 0 | G10: =COUNTA('TechStore Test Cases'!A36:A43) -> 8
B11: 4 | C11: 5.4 - Trang chủ, catalog và chi tiết sản phẩm | D11: =COUNTIF('TechStore Test Cases'!I45:I56,"Pass") -> 11 | E11: =COUNTIF('TechStore Test Cases'!I45:I56,"Fail") -> 1 | F11: =COUNTIF('TechStore Test Cases'!I45:I56,"Pending") -> 0 | G11: =COUNTA('TechStore Test Cases'!A45:A56) -> 12
B12: 5 | C12: 5.5 - Yêu thích | D12: =COUNTIF('TechStore Test Cases'!I58:I62,"Pass") -> 4 | E12: =COUNTIF('TechStore Test Cases'!I58:I62,"Fail") -> 1 | F12: =COUNTIF('TechStore Test Cases'!I58:I62,"Pending") -> 0 | G12: =COUNTA('TechStore Test Cases'!A58:A62) -> 5
B13: 6 | C13: 5.6 - Giỏ hàng | D13: =COUNTIF('TechStore Test Cases'!I64:I73,"Pass") -> 10 | E13: =COUNTIF('TechStore Test Cases'!I64:I73,"Fail") -> 0 | F13: =COUNTIF('TechStore Test Cases'!I64:I73,"Pending") -> 0 | G13: =COUNTA('TechStore Test Cases'!A64:A73) -> 10
B14: 7 | C14: 5.7 - Hồ sơ và địa chỉ | D14: =COUNTIF('TechStore Test Cases'!I75:I84,"Pass") -> 10 | E14: =COUNTIF('TechStore Test Cases'!I75:I84,"Fail") -> 0 | F14: =COUNTIF('TechStore Test Cases'!I75:I84,"Pending") -> 0 | G14: =COUNTA('TechStore Test Cases'!A75:A84) -> 10
B15: 8 | C15: 5.8 - Checkout COD và tạo đơn | D15: =COUNTIF('TechStore Test Cases'!I86:I97,"Pass") -> 12 | E15: =COUNTIF('TechStore Test Cases'!I86:I97,"Fail") -> 0 | F15: =COUNTIF('TechStore Test Cases'!I86:I97,"Pending") -> 0 | G15: =COUNTA('TechStore Test Cases'!A86:A97) -> 12
B16: 9 | C16: 5.9 - Lịch sử, chi tiết và hủy đơn | D16: =COUNTIF('TechStore Test Cases'!I99:I108,"Pass") -> 10 | E16: =COUNTIF('TechStore Test Cases'!I99:I108,"Fail") -> 0 | F16: =COUNTIF('TechStore Test Cases'!I99:I108,"Pending") -> 0 | G16: =COUNTA('TechStore Test Cases'!A99:A108) -> 10
B17: 10 | C17: 5.10 - VNPay sandbox | D17: =COUNTIF('TechStore Test Cases'!I110:I123,"Pass") -> 13 | E17: =COUNTIF('TechStore Test Cases'!I110:I123,"Fail") -> 1 | F17: =COUNTIF('TechStore Test Cases'!I110:I123,"Pending") -> 0 | G17: =COUNTA('TechStore Test Cases'!A110:A123) -> 14
B18: 11 | C18: 5.11 - Admin dashboard và báo cáo | D18: =COUNTIF('TechStore Test Cases'!I125:I132,"Pass") -> 8 | E18: =COUNTIF('TechStore Test Cases'!I125:I132,"Fail") -> 0 | F18: =COUNTIF('TechStore Test Cases'!I125:I132,"Pending") -> 0 | G18: =COUNTA('TechStore Test Cases'!A125:A132) -> 8
B19: 12 | C19: 5.12 - Admin catalog, sản phẩm và tài sản | D19: =COUNTIF('TechStore Test Cases'!I134:I157,"Pass") -> 24 | E19: =COUNTIF('TechStore Test Cases'!I134:I157,"Fail") -> 0 | F19: =COUNTIF('TechStore Test Cases'!I134:I157,"Pending") -> 0 | G19: =COUNTA('TechStore Test Cases'!A134:A157) -> 24
B20: 13 | C20: 5.13 - Admin đơn hàng và người dùng | D20: =COUNTIF('TechStore Test Cases'!I159:I171,"Pass") -> 13 | E20: =COUNTIF('TechStore Test Cases'!I159:I171,"Fail") -> 0 | F20: =COUNTIF('TechStore Test Cases'!I159:I171,"Pending") -> 0 | G20: =COUNTA('TechStore Test Cases'!A159:A171) -> 13
B21: 14 | C21: 6.1 - CSRF, session, quyền và dữ liệu đầu vào | D21: =COUNTIF('TechStore Test Cases'!I173:I184,"Pass") -> 9 | E21: =COUNTIF('TechStore Test Cases'!I173:I184,"Fail") -> 3 | F21: =COUNTIF('TechStore Test Cases'!I173:I184,"Pending") -> 0 | G21: =COUNTA('TechStore Test Cases'!A173:A184) -> 12
B22: 15 | C22: 6.2 - Database, transaction và cạnh tranh | D22: =COUNTIF('TechStore Test Cases'!I186:I193,"Pass") -> 7 | E22: =COUNTIF('TechStore Test Cases'!I186:I193,"Fail") -> 1 | F22: =COUNTIF('TechStore Test Cases'!I186:I193,"Pending") -> 0 | G22: =COUNTA('TechStore Test Cases'!A186:A193) -> 8
B23: 16 | C23: 6.3 - Responsive, trình duyệt và accessibility | D23: =COUNTIF('TechStore Test Cases'!I195:I205,"Pass") -> 10 | E23: =COUNTIF('TechStore Test Cases'!I195:I205,"Fail") -> 1 | F23: =COUNTIF('TechStore Test Cases'!I195:I205,"Pending") -> 0 | G23: =COUNTA('TechStore Test Cases'!A195:A205) -> 11
B24: 17 | C24: 6.4 - Hiệu năng, ổn định và deploy | D24: =COUNTIF('TechStore Test Cases'!I207:I216,"Pass") -> 9 | E24: =COUNTIF('TechStore Test Cases'!I207:I216,"Fail") -> 1 | F24: =COUNTIF('TechStore Test Cases'!I207:I216,"Pending") -> 0 | G24: =COUNTA('TechStore Test Cases'!A207:A216) -> 10
C26: Sub total | D26: =SUM(D8:D24) -> 179 | E26: =SUM(E8:E24) -> 9 | F26: =SUM(F8:F24) -> 0 | G26: =SUM(G8:G24) -> 188
C28: Test coverage | E28: =IF(G26=0,0,(D26+E26)*100/G26) -> 100 | F28: %
C29: Test successful coverage | E29: =IF(G26=0,0,D26*100/G26) -> 95.212766 | F29: %
